{"timestamp": "2025-04-27 17:44:16,541", "level": "CRITICAL", "name": "node", "message": "Failed to connect to Redis Cluster: 'dict' object has no attribute 'name'", "exception": "Traceback (most recent call last):\n  File \"/app/node_server.py\", line 52, in <module>\n    r = RedisCluster(startup_nodes=startup_nodes, decode_responses=True)\n        ^^^^^^^^^^^^^^^^^^^^^^^^^^^^^^^^^^^^^^^^^^^^^^^^^^^^^^^^^^^^^^^^\n  File \"/usr/local/lib/python3.12/site-packages/redis/cluster.py\", line 641, in __init__\n    self.nodes_manager = NodesManager(\n                         ^^^^^^^^^^^^^\n  File \"/usr/local/lib/python3.12/site-packages/redis/cluster.py\", line 1341, in __init__\n    self.populate_startup_nodes(startup_nodes)\n  File \"/usr/local/lib/python3.12/site-packages/redis/cluster.py\", line 1468, in populate_startup_nodes\n    self.startup_nodes[n.name] = n\n                       ^^^^^^\nAttributeError: 'dict' object has no attribute 'name'", "taskName": null}
